  0%|          | 0/50 [00:16<?, ?it/s]
Error durante el experimento: Caught RuntimeError in DataLoader worker process 1.
Original Traceback (most recent call last):
  File "/home/josei/workspace/RN/RNENV/lib64/python3.12/site-packages/torch/utils/data/_utils/worker.py", line 351, in _worker_loop
    data = fetcher.fetch(index)  # type: ignore[possibly-undefined]
           ^^^^^^^^^^^^^^^^^^^^
  File "/home/josei/workspace/RN/RNENV/lib64/python3.12/site-packages/torch/utils/data/_utils/fetch.py", line 55, in fetch
    return self.collate_fn(data)
           ^^^^^^^^^^^^^^^^^^^^^
  File "/home/josei/workspace/RN/RNENV/lib64/python3.12/site-packages/torch/utils/data/_utils/collate.py", line 398, in default_collate
    return collate(batch, collate_fn_map=default_collate_fn_map)
           ^^^^^^^^^^^^^^^^^^^^^^^^^^^^^^^^^^^^^^^^^^^^^^^^^^^^^
  File "/home/josei/workspace/RN/RNENV/lib64/python3.12/site-packages/torch/utils/data/_utils/collate.py", line 212, in collate
    collate(samples, collate_fn_map=collate_fn_map)
  File "/home/josei/workspace/RN/RNENV/lib64/python3.12/site-packages/torch/utils/data/_utils/collate.py", line 155, in collate
    return collate_fn_map[elem_type](batch, collate_fn_map=collate_fn_map)
           ^^^^^^^^^^^^^^^^^^^^^^^^^^^^^^^^^^^^^^^^^^^^^^^^^^^^^^^^^^^^^^^
  File "/home/josei/workspace/RN/RNENV/lib64/python3.12/site-packages/torch/utils/data/_utils/collate.py", line 272, in collate_tensor_fn
    return torch.stack(batch, 0, out=out)
           ^^^^^^^^^^^^^^^^^^^^^^^^^^^^^^
RuntimeError: torch.cat(): input types can't be cast to the desired output type Byte

Experimento terminado para efficientnet_b5.sw_in12k__bn_drp_unfreeze_416_cj_cp_aggr_da
[34m[1mwandb[0m: [33mWARNING[0m Fatal error while uploading data. Some run data will not be synced, but it will still be written to disk. Use `wandb sync` at the end of the run to try uploading.
