  0%|          | 0/50 [00:04<?, ?it/s]
Error durante el experimento: Caught RuntimeError in DataLoader worker process 0.
Original Traceback (most recent call last):
  File "/home/josei/workspace/RN/RNENV/lib64/python3.12/site-packages/torch/utils/data/_utils/worker.py", line 351, in _worker_loop
    data = fetcher.fetch(index)  # type: ignore[possibly-undefined]
           ^^^^^^^^^^^^^^^^^^^^
  File "/home/josei/workspace/RN/RNENV/lib64/python3.12/site-packages/torch/utils/data/_utils/fetch.py", line 55, in fetch
    return self.collate_fn(data)
           ^^^^^^^^^^^^^^^^^^^^^
  File "/home/josei/workspace/RN/RNENV/lib64/python3.12/site-packages/torch/utils/data/_utils/collate.py", line 398, in default_collate
    return collate(batch, collate_fn_map=default_collate_fn_map)
           ^^^^^^^^^^^^^^^^^^^^^^^^^^^^^^^^^^^^^^^^^^^^^^^^^^^^^
  File "/home/josei/workspace/RN/RNENV/lib64/python3.12/site-packages/torch/utils/data/_utils/collate.py", line 212, in collate
    collate(samples, collate_fn_map=collate_fn_map)
  File "/home/josei/workspace/RN/RNENV/lib64/python3.12/site-packages/torch/utils/data/_utils/collate.py", line 155, in collate
    return collate_fn_map[elem_type](batch, collate_fn_map=collate_fn_map)
           ^^^^^^^^^^^^^^^^^^^^^^^^^^^^^^^^^^^^^^^^^^^^^^^^^^^^^^^^^^^^^^^
  File "/home/josei/workspace/RN/RNENV/lib64/python3.12/site-packages/torch/utils/data/_utils/collate.py", line 272, in collate_tensor_fn
    return torch.stack(batch, 0, out=out)
           ^^^^^^^^^^^^^^^^^^^^^^^^^^^^^^
RuntimeError: stack expects each tensor to be equal size, but got [3, 372, 388] at entry 0 and [3, 374, 355] at entry 1

Experimento terminado para efficientnet_b5.sw_in12k__lots_aug_bn_drp_8_VAL
Running experiment: efficientnet_b5.sw_in12k__lots_aug_bn_drp_8_VAL
Using device: cuda
